<mujoco model="Dex5-URDF-R">
  <compiler angle="radian" meshdir="./meshes/" autolimits="true" />

  <default>
    <default class="dex5">
      <default class="visual">
        <geom group="2" type="mesh" density="0" material="silver" contype="0" conaffinity="0"/>
      </default>
      <default class="collision">
        <geom group="3" rgba=".2 .6 .2 .3" type="mesh" contype="1" conaffinity="1"/>
      </default>
      <site group="5" rgba="1 0 0 1"/>
    </default>
  </default>

  <asset>
    <material name="black" rgba="0.25 0.25 0.25 1"/>
    <material name="white" rgba="0.9 0.9 0.9 1"/>
    <mesh name="base_link00" file="base_link00.STL"/>
    <mesh name="Link_11R" file="Link_11R.STL"/>
    <mesh name="Link_12R" file="Link_12R.STL"/>
    <mesh name="Link_13R" file="Link_13R.STL"/>
    <mesh name="Link_14R" file="Link_14R.STL"/>
    <mesh name="Link_21R" file="Link_21R.STL"/>
    <mesh name="Link_22R" file="Link_22R.STL"/>
    <mesh name="Link_23R" file="Link_23R.STL"/>
    <mesh name="Link_24R" file="Link_24R.STL"/>
    <mesh name="Link_31R" file="Link_31R.STL"/>
    <mesh name="Link_32R" file="Link_32R.STL"/>
    <mesh name="Link_33R" file="Link_33R.STL"/>
    <mesh name="Link_34R" file="Link_34R.STL"/>
    <mesh name="Link_41R" file="Link_41R.STL"/>
    <mesh name="Link_42R" file="Link_42R.STL"/>
    <mesh name="Link_43R" file="Link_43R.STL"/>
    <mesh name="Link_44R" file="Link_44R.STL"/>
    <mesh name="Link_51R" file="Link_51R.STL"/>
    <mesh name="Link_52R" file="Link_52R.STL"/>
    <mesh name="Link_53R" file="Link_53R.STL"/>
    <mesh name="Link_54R" file="Link_54R.STL"/>
  </asset>

  <worldbody>
    <body name="root">
      <body name="base_link00">
        <inertial pos="-0.023027 0.027982 -0.017178" quat="0.557064 0.409754 -0.525049 0.496089" mass="0.685702" diaginertia="0.00106865 0.000784347 0.000598472"/>
        <geom class="visual" material="black" mesh="base_link00"/>
        <geom class="collision" material="black" mesh="base_link00"/>
        <body name="Link_11R" pos="0 0 0.01435">
          <inertial pos="-0.008418 0.000123 -0.003247" quat="0.0170223 0.756235 0.00551611 0.654055" mass="0.02363" diaginertia="3.88743e-06 3.60721e-06 2.61432e-06"/>
          <joint name="Yaw_11R" pos="0 0 0" axis="0 0 1" range="-0.5867 0.6803" actuatorfrcrange="-0.93 0.93"/>
          <geom class="visual" material="black" mesh="Link_11R"/>
          <geom class="collision" material="black" mesh="Link_11R"/>
          <body name="Link_12R" pos="-1.06041e-05 0 0" quat="0.707107 0.707107 0 0">
            <inertial pos="0.014668 1.3e-05 -0.004099" quat="0.408251 0.575467 0.577544 0.410624" mass="0.015809" diaginertia="4.04972e-06 3.70479e-06 2.98874e-06"/>
            <joint name="Roll_12R" pos="0 0 0" axis="0 0 1" range="0 1.8151" actuatorfrcrange="-0.93 0.93"/>
            <geom class="visual" material="black" mesh="Link_12R"/>
            <geom class="collision" material="black" mesh="Link_12R"/>
            <body name="Link_13R" pos="0.0335 0 -0.006" quat="0.707107 -0.707107 -5.48304e-06 -5.48304e-06">
              <inertial pos="0.018557 -0.006933 0.000159" quat="-0.0509898 0.706282 0.0461116 0.704585" mass="0.06674" diaginertia="2.3879e-05 2.31949e-05 8.83599e-06"/>
              <joint name="Pitch_13R" pos="0 0 0" axis="0 0 1" range="0 1.76523" actuatorfrcrange="-0.93 0.93"/>
              <geom class="visual" material="black" mesh="Link_13R"/>
              <geom class="collision" material="black" mesh="Link_13R"/>
              <body name="Link_14R" pos="0.036609 -0.0053654 0">
                <inertial pos="0.028085 0.003322 0.000472" quat="0.472849 0.506452 0.510414 0.50931" mass="0.020073" diaginertia="6.09065e-06 5.6186e-06 1.9266e-06"/>
                <joint name="Pitch_14R" pos="0 0 0" axis="0 0 1" range="0 1.6406" actuatorfrcrange="-0.93 0.93"/>
                <geom class="visual" material="black" mesh="Link_14R"/>
                <geom class="collision" material="black" mesh="Link_14R"/>
                <!-- <body name="TH_Tip_R">
                  <geom class="visual" material="black" mesh="TH_Tip_R"/>
                  <geom class="collision" material="black" mesh="TH_Tip_R"/>
                </body> -->
              </body>
            </body>
          </body>
        </body>
        <body name="Link_21R" pos="0.01 0.073143 -0.0034702" quat="0.707105 0 0 0.707108">
          <inertial pos="0.007826 -5e-06 -0.004125" quat="0.286741 0.642193 0.652687 0.281721" mass="0.004497" diaginertia="1.37516e-07 1.30215e-07 5.57971e-08"/>
          <joint name="Roll_21R" pos="0 0 0" axis="0 0 1" range="-0.38397 0.38397" actuatorfrcrange="-0.93 0.93"/>
          <geom class="visual" material="black" mesh="Link_21R"/>
          <geom class="collision" material="black" mesh="Link_21R"/>
          <body name="Link_22R" pos="0.0042 0 0" quat="0.707107 0.707107 0 0">
            <inertial pos="0.021242 -0.005936 5.9e-05" quat="-0.014401 0.706631 0.017695 0.707214" mass="0.017982" diaginertia="4.37013e-06 4.08705e-06 1.20085e-06"/>
            <joint name="Pitch_22R" pos="0 0 0" axis="0 0 1" range="0 1.5708" actuatorfrcrange="-0.93 0.93"/>
            <geom class="visual" material="black" mesh="Link_22R"/>
            <geom class="collision" material="black" mesh="Link_22R"/>
            <body name="Link_23R" pos="0.04 0 0">
              <inertial pos="0.011393 -0.005777 1e-06" quat="0.27941 0.648386 -0.281286 0.649926" mass="0.012776" diaginertia="8.29432e-07 6.90028e-07 5.7959e-07"/>
              <joint name="Pitch_23R" pos="0 0 0" axis="0 0 1" range="0 1.68424" actuatorfrcrange="-0.93 0.93"/>
              <geom class="visual" material="black" mesh="Link_23R"/>
              <geom class="collision" material="black" mesh="Link_23R"/>
              <body name="Link_24R" pos="0.0209846 0.000804304 0">
                <inertial pos="0.009354 -0.004824 7.2e-05" quat="0.468377 0.474783 0.524464 0.529285" mass="0.00639891" diaginertia="1.47892e-06 1.44823e-06 4.83167e-07"/>
                <joint name="Pitch_24R" pos="0 0 0" axis="0 0 1" range="0 1.39626" actuatorfrcrange="-0.93 0.93"/>
                <geom class="visual" material="black" mesh="Link_24R"/>
                <geom class="collision" material="black" mesh="Link_24R"/>
                <!-- <body name="FF_Tip_R">
                  <geom class="visual" material="black" mesh="FF_Tip_R"/>
                  <geom class="collision" material="black" mesh="FF_Tip_R"/>
                </body> -->
              </body>
            </body>
          </body>
        </body>
        <body name="Link_31R" pos="-0.012 0.077143 -0.0034702" quat="0.707105 0 0 0.707108">
          <inertial pos="0.007826 -5e-06 -0.004125" quat="0.286741 0.642193 0.652687 0.281721" mass="0.004497" diaginertia="1.37516e-07 1.30215e-07 5.57971e-08"/>
          <joint name="Roll_31R" pos="0 0 0" axis="0 0 1" range="-0.38397 0.38397" actuatorfrcrange="-0.93 0.93"/>
          <geom class="visual" material="black" mesh="Link_31R"/>
          <geom class="collision" material="black" mesh="Link_31R"/>
          <body name="Link_32R" pos="0.0042 0 0" quat="0.707107 0.707107 0 0">
            <inertial pos="0.021242 -0.005936 5.9e-05" quat="-0.014401 0.706631 0.017695 0.707214" mass="0.017982" diaginertia="4.37013e-06 4.08705e-06 1.20085e-06"/>
            <joint name="Pitch_32R" pos="0 0 0" axis="0 0 1" range="0 1.5708" actuatorfrcrange="-0.93 0.93"/>
            <geom class="visual" material="black" mesh="Link_32R"/>
            <geom class="collision" material="black" mesh="Link_32R"/>
            <body name="Link_33R" pos="0.04 0 0">
              <inertial pos="0.011393 -0.005777 1e-06" quat="0.27941 0.648386 -0.281286 0.649926" mass="0.012776" diaginertia="8.29432e-07 6.90028e-07 5.7959e-07"/>
              <joint name="Pitch_33R" pos="0 0 0" axis="0 0 1" range="0 1.68424" actuatorfrcrange="-0.93 0.93"/>
              <geom class="visual" material="black" mesh="Link_33R"/>
              <geom class="collision" material="black" mesh="Link_33R"/>
              <body name="Link_34R" pos="0.0209846 0.000804304 0">
                <inertial pos="0.009354 -0.004824 7.2e-05" quat="0.468377 0.474783 0.524464 0.529285" mass="0.00639891" diaginertia="1.47892e-06 1.44823e-06 4.83167e-07"/>
                <joint name="Pitch_34R" pos="0 0 0" axis="0 0 1" range="0 1.39626" actuatorfrcrange="-0.93 0.93"/>
                <geom class="visual" material="black" mesh="Link_34R"/>
                <geom class="collision" material="black" mesh="Link_34R"/>
                <!-- <body name="MF_Tip_R">
                  <geom class="visual" material="black" mesh="MF_Tip_R"/>
                  <geom class="collision" material="black" mesh="MF_Tip_R"/>
                </body> -->
              </body>
            </body>
          </body>
        </body>
        <body name="Link_41R" pos="-0.034 0.073143 -0.0034702" quat="0.707105 0 0 0.707108">
          <inertial pos="0.007826 -5e-06 -0.004125" quat="0.286741 0.642193 0.652687 0.281721" mass="0.004497" diaginertia="1.37516e-07 1.30215e-07 5.57971e-08"/>
          <joint name="Roll_41R" pos="0 0 0" axis="0 0 1" range="-0.38397 0.38397" actuatorfrcrange="-0.93 0.93"/>
          <geom class="visual" material="black" mesh="Link_41R"/>
          <geom class="collision" material="black" mesh="Link_41R"/>
          <body name="Link_42R" pos="0.0042 0 0" quat="0.707107 0.707107 0 0">
            <inertial pos="0.021242 -0.005936 5.9e-05" quat="-0.014401 0.706631 0.017695 0.707214" mass="0.017982" diaginertia="4.37013e-06 4.08705e-06 1.20085e-06"/>
            <joint name="Pitch_42R" pos="0 0 0" axis="0 0 1" range="0 1.5708" actuatorfrcrange="-0.93 0.93"/>
            <geom class="visual" material="black" mesh="Link_42R"/>
            <geom class="collision" material="black" mesh="Link_42R"/>
            <body name="Link_43R" pos="0.04 0 0">
              <inertial pos="0.011393 -0.005777 1e-06" quat="0.27941 0.648386 -0.281286 0.649926" mass="0.012776" diaginertia="8.29432e-07 6.90028e-07 5.7959e-07"/>
              <joint name="Pitch_43R" pos="0 0 0" axis="0 0 1" range="0 1.6842" actuatorfrcrange="-0.93 0.93"/>
              <geom class="visual" material="black" mesh="Link_43R"/>
              <geom class="collision" material="black" mesh="Link_43R"/>
              <body name="Link_44R" pos="0.0209846 0.000804304 0">
                <inertial pos="0.009354 -0.004824 7.2e-05" quat="0.468377 0.474783 0.524464 0.529285" mass="0.00639891" diaginertia="1.47892e-06 1.44823e-06 4.83167e-07"/>
                <joint name="Pitch_44R" pos="0 0 0" axis="0 0 1" range="0 1.3963" actuatorfrcrange="-0.93 0.93"/>
                <geom class="visual" material="black" mesh="Link_44R"/>
                <geom class="collision" material="black" mesh="Link_44R"/>
                <!-- <body name="RF_Tip_R">
                  <geom class="visual" material="black" mesh="RF_Tip_R"/>
                  <geom class="collision" material="black" mesh="RF_Tip_R"/>
                </body>
              </body> -->
            </body>
          </body>
        </body>
        <body name="Link_51R" pos="-0.056 0.0691434 -0.00347022" quat="0.707107 0 0 0.707107">
          <inertial pos="0.007826 -5e-06 -0.004125" quat="0.286741 0.642193 0.652687 0.281721" mass="0.004497" diaginertia="1.37516e-07 1.30215e-07 5.57971e-08"/>
          <joint name="Roll_51R" pos="0 0 0" axis="0 0 1" range="-0.38397 0.38397" actuatorfrcrange="-0.93 0.93"/>
          <geom class="visual" material="black" mesh="Link_51R"/>
          <geom class="collision" material="black" mesh="Link_51R"/>
          <body name="Link_52R" pos="0.0042 0 0" quat="0.707107 0.707107 0 0">
            <inertial pos="0.021242 -0.005936 5.9e-05" quat="-0.014401 0.706631 0.017695 0.707214" mass="0.017982" diaginertia="4.37013e-06 4.08705e-06 1.20085e-06"/>
            <joint name="Pitch_52R" pos="0 0 0" axis="0 0 1" range="0 1.5708" actuatorfrcrange="-0.93 0.93"/>
            <geom class="visual" material="black" mesh="Link_52R"/>
            <geom class="collision" material="black" mesh="Link_52R"/>
            <body name="Link_53R" pos="0.04 0 0">
              <inertial pos="0.011393 -0.005777 1e-06" quat="0.27941 0.648386 -0.281286 0.649926" mass="0.012776" diaginertia="8.29432e-07 6.90028e-07 5.7959e-07"/>
              <joint name="Pitch_53R" pos="0 0 0" axis="0 0 1" range="0 1.6842" actuatorfrcrange="-0.93 0.93"/>
              <geom class="visual" material="black" mesh="Link_53R"/>
              <geom class="collision" material="black" mesh="Link_53R"/>
              <body name="Link_54R" pos="0.0209846 0.000804304 0">
                <inertial pos="0.009354 -0.004824 7.2e-05" quat="0.468377 0.474783 0.524464 0.529285" mass="0.00639891" diaginertia="1.47892e-06 1.44823e-06 4.83167e-07"/>
                <joint name="Pitch_54R" pos="0 0 0" axis="0 0 1" range="0 1.3963" actuatorfrcrange="-0.93 0.93"/>
                <geom class="visual" material="black" mesh="Link_54R"/>
                <geom class="collision" material="black" mesh="Link_54R"/>
                <!-- <body name="LF_Tip_R">
                  <geom class="visual" material="black" mesh="LF_Tip_R"/>
                  <geom class="collision" material="black" mesh="LF_Tip_R"/>
                </body> -->
              </body>
            </body>
          </body>
        </body>
      </body>
    </body>
  </worldbody>

  <contact>
    <exclude body1="base_link00" body2="Link_12R"/>
    <exclude body1="base_link00" body2="Link_13R"/>
    <exclude body1="base_link00" body2="Link_22R"/>
    <exclude body1="base_link00" body2="Link_32R"/>
    <exclude body1="base_link00" body2="Link_42R"/>
    <exclude body1="base_link00" body2="Link_52R"/>
  </contact>


</mujoco>
